Workbook
Name ClientData: Client!$1:$152
Name ClientID: Link!$O$3
Name Codes: Link!$C$8:$D$112
Name DedCode: Link!$J$3
Name DedEmp: Link!$J$2
Name DedName: Link!$J$4
Name DeductionCodes: Link!$I$8:$K$50
Name DeductionData: Deductions!$A$1:$K$1638
Name DedValue: Link!$J$5
Name EmpID: Link!$D$2
Name EmpName: Link!$D$3
Name IgnoreCodes: Link!$F$8:$G$39
Name MinDiff: Link!$D$4
Name SBCcodes: Link!$M$8:$P$65
Name SBCdata: SBC!$A$1:$S$1000
Name SBCID: Link!$O$2
Name SBCType: Link!$O$4
Name SysCode: Link!$G$3
Name SysEmpID: Link!$G$2
Name SysItemName: Link!$G$4
Name SystemData: System!$A$1:$L$3000
Name SysValue: Link!$G$5

Sheet הערות
A1: בס"ד
A4: 1 | B4: בגליון DEDUCTIONS יש רכיבים 13 ו- 16 שאין להם ביטוי בנתוני הלקוח
A5: 2 | B5: בגליון DEDUCTIONS יש רכיב 9 שמתייחס להחזרי הוצאות. בנתוני הלקוח זה רק תמורה ממכירת אופציות. צריך להבין מה עושים עם שאר החזרי ההוצאות
A6: 3 | B6: בגלל שמסכמים את כל הרכיבים שיש להם אותו מספר רכיב, אז בגליון הממצאים, אין התייחסות לשםפ הרכיב בנתוני הלקוח - כיון שיש מספר רכיבים עם אותו קוד

Sheet Client
A1: No. | B1: ID | C1: Z-ID | D1: Employee's name | E1: Department - Cost Centre | F1: Employee Class | G1: Employment Status | H1: Start date | I1: End date | J1: New Annual salaries | K1: Payroll Comments | L1: Salary | M1: Global overtime | N1: Total - Monthly | O1: ESPP Contribution % | P1: ESPP Contribution - Amount | Q1: ESPP Catchups for December 2024 | R1: CEO Bonus | S1: Travel Allowance | T1: Commissions | U1: Phone value | V1: BIK- Birthday Gift (to be grossed up) | W1: Referral Bonus | X1: Salary Arrears- Aug'25 & Sept'25 | Y1: Israel First Year Bonus Scheme: | Z1: Retention Bonus | AA1: Corporate Bonus | AB1: BIK Health Insurance (to be grossed up) | AC1: BIK - Mobile Reimbursment - to be grossed up | AD1: BIK - Meals - October 2025 (EE bears the tax) | AE1: BIK Lunch Meals- (to be grossed up) October 2025 | AF1: BIK Dinner Meals- (to be grossed up) October 2025 | AG1: BIK -Holiday Gifts- Sept 2025 (taxes borne by employer) | AH1: Wedding Gift (need to pay and gross up) | AI1: ESPP refunds | AJ1: Tution Reimbursement Benefit- Pay and Tax will borne by EE | AK1: Spot Bonus- EE bears the tax | AL1: Patent Bonus- EE bears the tax | AM1: Standard Days | AN1: Standard hours | AO1: Actual working days | AP1: Actual work hours | AQ1: Vacation days | AR1: Sick days | AS1: Reserve Duty | AT1: Advance Payment | AU1: Reimbursement | AV1: Comments
A2: 4 | B2: 306689712 | C2: Z22252 | D2: Leonid Geldin | E2: 2450 | F2: Fulltime Employee | G2: Active | H2: 43788 | J2: 630230.22 | L2: =J2/12*70% -> 36763.429 | M2: =J2/12*30% -> 15755.755 | N2: =SUM(L2:M2) -> 52519.185 | O2: 15 | P2: =(N2+W2+X2+AA2+T2+R2)*O2% -> 7877.8777 | S2: 315 | V2: 0 | AB2: 154 | AC2: 115 | AD2: 1000 | AM2: 21 | AN2: =AM2*8.4 -> 176.4 | AO2: =AM2-AQ2-AR2 -> 19.5 | AP2: =AO2*8.4 -> 163.8 | AQ2: 1.5 | AR2: 0 | AU2: 1580
A3: 6 | B3: 32655482 | C3: Z22251 | D3: Nadav Pozmantir | E3: 2410 | F3: Fulltime Employee | G3: Active | H3: 43905 | J3: 625007 | L3: =J3/12*70% -> 36458.742 | M3: =J3/12*30% -> 15625.175 | N3: =SUM(L3:M3) -> 52083.917 | O3: 15 | P3: =(N3+W3+X3+AA3+T3+R3)*O3% -> 7812.5875 | S3: 315 | V3: 0 | AB3: 154 | AC3: 115 | AD3: 1000 | AM3: 21 | AN3: =AM3*8.4 -> 176.4 | AO3: =AM3-AQ3-AR3 -> 8 | AP3: =AO3*8.4 -> 67.2 | AQ3: 3 | AR3: 10
A4: 8 | B4: 65965949 | C4: Z22256 | D4: Ido Katz | E4: 2410 | F4: Fulltime Employee | G4: Active | H4: 44005 | J4: 612002.66 | L4: =J4/12*70% -> 35700.155 | M4: =J4/12*30% -> 15300.067 | N4: =SUM(L4:M4) -> 51000.222 | O4: 15 | P4: =(N4+W4+X4+AA4+T4+R4)*O4% -> 7650.0333 | S4: 315 | V4: 0 | AB4: 154 | AC4: 115 | AD4: 1000 | AM4: 21 | AN4: =AM4*8.4 -> 176.4 | AO4: =AM4-AQ4-AR4 -> 19 | AP4: =AO4*8.4 -> 159.6 | AQ4: 0 | AR4: 2 | AU4: 1860
A5: 11 | B5: 35699578 | C5: Z22254 | D5: Elad Kolberg | E5: 2885 | F5: Fulltime Employee | G5: Active | H5: 44087 | J5: 735201.69 | L5: =J5/12*70% -> 42886.765 | M5: =J5/12*30% -> 18380.042 | N5: =SUM(L5:M5) -> 61266.807 | O5: 10 | P5: =(N5+W5+X5+AA5+T5+R5)*O5% -> 6126.6807 | S5: 315 | V5: 0 | AB5: 154 | AC5: 115 | AD5: 1000 | AM5: 21 | AN5: =AM5*8.4 -> 176.4 | AO5: =AM5-AQ5-AR5 -> 20 | AP5: =AO5*8.4 -> 168 | AQ5: 0 | AR5: 1
A6: 12 | B6: 39997325 | C6: Z22255 | D6: Ariel Nemtzov | E6: 2410 | F6: Fulltime Employee | G6: Active | H6: 44087 | J6: 555531 | L6: =J6/12*70% -> 32405.975 | M6: =J6/12*30% -> 13888.275 | N6: =SUM(L6:M6) -> 46294.25 | O6: 15 | P6: =(N6+W6+X6+AA6+T6+R6)*O6% -> 6944.1375 | S6: 315 | V6: 0 | AB6: 154 | AC6: 115 | AD6: 1000 | AM6: 21 | AN6: =AM6*8.4 -> 176.4 | AO6: =AM6-AQ6-AR6 -> 20 | AP6: =AO6*8.4 -> 168 | AQ6: 0 | AR6: 1 | AU6: 391
A7: 14 | B7: 38075941 | C7: Z22260 | D7: Danny Sabag | E7: 2410 | F7: Fulltime Employee | G7: Active | H7: 44122 | J7: 546551 | L7: =J7/12*70% -> 31882.142 | M7: =J7/12*30% -> 13663.775 | N7: =SUM(L7:M7) -> 45545.917 | O7: 8 | P7: =(N7+W7+X7+AA7+T7+R7)*O7% -> 3643.6733 | S7: 315 | V7: 0 | AB7: 154 | AC7: 115 | AD7: 999.96 | AM7: 21 | AN7: =AM7*8.4 -> 176.4 | AO7: =AM7-AQ7-AR7 -> 21 | AP7: =AO7*8.4 -> 176.4 | AQ7: 0 | AR7: 0 | AU7: 208
A8: 15 | B8: 66713272 | C8: Z22259 | D8: Oz Molaim | E8: 2410 | F8: Fulltime Employee | G8: Active | H8: 44130 | J8: 530201 | L8: =J8/12*70% -> 30928.392 | M8: =J8/12*30% -> 13255.025 | N8: =SUM(L8:M8) -> 44183.417 | O8: 15 | P8: =(N8+W8+X8+AA8+T8+R8)*O8% -> 6627.5125 | S8: 315 | V8: 0 | AB8: 154 | AC8: 115 | AD8: 940.5 | AM8: 21 | AN8: =AM8*8.4 -> 176.4 | AO8: =AM8-AQ8-AR8 -> 20 | AP8: =AO8*8.4 -> 168 | AQ8: 0 | AR8: 1
A9: 16 | B9: 306939349 | C9: Z22261 | D9: Maya Zax | E9: 2180 | F9: Parttime Employee 60% working position | G9: Active | H9: 44164 | J9: 256261.37 | K9: Parttime Employee 60% working position | L9: =J9/12*70% -> 14948.58 | M9: =J9/12*30% -> 6406.5342 | N9: =SUM(L9:M9) -> 21355.114 | O9: 0 | P9: =(N9+W9+X9+AA9+T9+R9)*O9% -> 0 | S9: 315 | V9: 0 | AB9: 154 | AC9: 115 | AD9: 700 | AM9: 21 | AN9: =AM9*8.4 -> 176.4 | AO9: =AM9-AQ9-AR9 -> 21 | AP9: =AO9*8.4 -> 176.4 | AQ9: 0 | AR9: 0
A10: 17 | B10: 300123221 | C10: Z22405 | D10: Adi Adrai | E10: 2410 | F10: Fulltime Employee | G10: Active | H10: 44350 | J10: 610388 | L10: =J10/12*70% -> 35605.967 | M10: =J10/12*30% -> 15259.7 | N10: =SUM(L10:M10) -> 50865.667 | O10: 15 | P10: =(N10+W10+X10+AA10+T10+R10)*O10% -> 7629.85 | S10: 315 | V10: 0 | AB10: 154 | AC10: 115 | AD10: 738 | AM10: 21 | AN10: =AM10*8.4 -> 176.4 | AO10: =AM10-AQ10-AR10 -> 11 | AP10: =AO10*8.4 -> 92.4 | AQ10: 10 | AR10: 0
A11: 21 | B11: 332407659 | C11: Z22756 | D11: Esther Shteinberg | E11: 2180 | F11: Fulltime Employee | G11: Active | H11: 44395 | J11: 486311 | L11: =J11/12*70% -> 28368.142 | M11: =J11/12*30% -> 12157.775 | N11: =SUM(L11:M11) -> 40525.917 | O11: 15 | P11: =(N11+W11+X11+AA11+T11+R11)*O11% -> 6078.8875 | S11: 315 | V11: 0 | AB11: 154 | AC11: 115 | AD11: 1000 | AM11: 21 | AN11: =AM11*8.4 -> 176.4 | AO11: =AM11-AQ11-AR11 -> 8 | AP11: =AO11*8.4 -> 67.2 | AQ11: 0 | AR11: 13
A12: 22 | B12: 201570793 | C12: Z22704 | D12: Adam Hudeda | E12: 2450 | F12: Fulltime Employee | G12: Active | H12: 44395 | J12: 505167 | L12: =J12/12*70% -> 29468.075 | M12: =J12/12*30% -> 12629.175 | N12: =SUM(L12:M12) -> 42097.25 | O12: 15 | P12: =(N12+W12+X12+AA12+T12+R12)*O12% -> 6314.5875 | S12: 315 | V12: 0 | AB12: 154 | AC12: 115 | AD12: 1000 | AM12: 21 | AN12: =AM12*8.4 -> 176.4 | AO12: =AM12-AQ12-AR12 -> 20 | AP12: =AO12*8.4 -> 168 | AQ12: 1 | AR12: 0 | AU12: 70
A13: 23 | B13: 27385756 | C13: Z22874 | D13: Ofer Yarom | E13: 2540 | F13: Fulltime Employee | G13: Active | H13: 44424 | J13: 779032.26 | L13: =J13/12*70% -> 45443.548 | M13: =J13/12*30% -> 19475.806 | N13: =SUM(L13:M13) -> 64919.355 | O13: 15 | P13: =(N13+W13+X13+AA13+T13+R13)*O13% -> 9737.9032 | S13: 315 | V13: 0 | AB13: 154 | AC13: 115 | AD13: 995.72 | AM13: 21 | AN13: =AM13*8.4 -> 176.4 | AO13: =AM13-AQ13-AR13 -> 21 | AP13: =AO13*8.4 -> 176.4 | AQ13: 0 | AR13: 0
A14: 24 | B14: 316377191 | C14: Z23095 | D14: Lilach Wimisiner | E14: 2410 | F14: Fulltime Employee | G14: Active | H14: 44437 | J14: 509230 | L14: =J14/12*70% -> 29705.083 | M14: =J14/12*30% -> 12730.75 | N14: =SUM(L14:M14) -> 42435.833 | O14: 15 | P14: =(N14+W14+X14+AA14+T14+R14)*O14% -> 6365.375 | S14: 315 | V14: 0 | AB14: 154 | AC14: 115 | AD14: 967.96 | AM14: 21 | AN14: =AM14*8.4 -> 176.4 | AO14: =AM14-AQ14-AR14 -> 21 | AP14: =AO14*8.4 -> 176.4 | AQ14: 0 | AR14: 0
A15: 26 | B15: 206350936 | C15: Z23096 | D15: Dani Rubin | E15: 2885 | F15: Fulltime Employee | G15: Active | H15: 44441 | J15: 530530 | L15: =J15/12*70% -> 30947.583 | M15: =J15/12*30% -> 13263.25 | N15: =SUM(L15:M15) -> 44210.833 | O15: 15 | P15: =(N15+W15+X15+AA15+T15+R15)*O15% -> 6631.625 | S15: 315 | V15: 0 | AB15: 154 | AC15: 115 | AD15: 1000 | AM15: 21 | AN15: =AM15*8.4 -> 176.4 | AO15: =AM15-AQ15-AR15 -> 16 | AP15: =AO15*8.4 -> 134.4 | AQ15: 5 | AR15: 0
A16: 27 | B16: 207763806 | C16: Z23077 | D16: Jonathan Assayag | E16: 2885 | F16: Fulltime Employee | G16: Active | H16: 44451 | J16: 499180 | L16: =J16/12*70% -> 29118.833 | M16: =J16/12*30% -> 12479.5 | N16: =SUM(L16:M16) -> 41598.333 | O16: 15 | P16: =(N16+W16+X16+AA16+T16+R16)*O16% -> 6239.75 | S16: 315 | V16: 0 | AB16: 154 | AC16: 115 | AD16: 1000 | AM16: 21 | AN16: =AM16*8.4 -> 176.4 | AO16: =AM16-AQ16-AR16 -> 21 | AP16: =AO16*8.4 -> 176.4 | AQ16: 0 | AR16: 0
A17: 30 | B17: 21598768 | C17: Z23336 | D17: Gal Shvinkelstein | E17: 2410 | F17: Fulltime Employee | G17: Active | H17: 44473 | J17: 488298.8 | L17: =J17/12*70% -> 28484.097 | M17: =J17/12*30% -> 12207.47 | N17: =SUM(L17:M17) -> 40691.567 | O17: 1 | P17: =(N17+W17+X17+AA17+T17+R17)*O17% -> 406.91567 | S17: 315 | V17: 0 | AB17: 154 | AC17: 115 | AD17: 1000 | AM17: 21 | AN17: =AM17*8.4 -> 176.4 | AO17: =AM17-AQ17-AR17 -> 19 | AP17: =AO17*8.4 -> 159.6 | AQ17: 2 | AR17: 0 | AU17: 40
A18: 32 | B18: 307604256 | C18: Z23259 | D18: Gal Sosin | E18: 2410 | F18: Fulltime Employee | G18: Active | H18: 44486 | J18: 637738.5 | L18: =J18/12*70% -> 37201.412 | M18: =J18/12*30% -> 15943.462 | N18: =SUM(L18:M18) -> 53144.875 | O18: 0 | P18: =(N18+W18+X18+AA18+T18+R18)*O18% -> 0 | S18: 315 | V18: 150 | AB18: 154 | AC18: 115 | AD18: 1000 | AM18: 21 | AN18: =AM18*8.4 -> 176.4 | AO18: =AM18-AQ18-AR18 -> 20 | AP18: =AO18*8.4 -> 168 | AQ18: 0 | AR18: 1
A19: 35 | B19: 201270642 | C19: Z23824 | D19: Keren Zilberman | E19: 1580 | F19: Fulltime Employee | G19: Active | H19: 44516 | J19: 252167 | L19: =J19/12*70% -> 14709.742 | M19: =J19/12*30% -> 6304.175 | N19: =SUM(L19:M19) -> 21013.917 | O19: 7 | P19: =(N19+W19+X19+AA19+T19+R19)*O19% -> 1470.9742 | S19: 315 | V19: 0 | AB19: 154 | AC19: 115 | AD19: 1000 | AM19: 21 | AN19: =AM19*8.4 -> 176.4 | AO19: =AM19-AQ19-AR19 -> 20 | AP19: =AO19*8.4 -> 168 | AQ19: 0 | AR19: 1
A20: 38 | B20: 36983187 | C20: Z23746 | D20: Avner Eizner | E20: 2410 | F20: Fulltime Employee | G20: Active | H20: 44521 | J20: 561479 | L20: =J20/12*70% -> 32752.942 | M20: =J20/12*30% -> 14036.975 | N20: =SUM(L20:M20) -> 46789.917 | O20: 15 | P20: =(N20+W20+X20+AA20+T20+R20)*O20% -> 7018.4875 | S20: 315 | V20: 0 | AB20: 154 | AC20: 115 | AD20: 1000 | AM20: 21 | AN20: =AM20*8.4 -> 176.4 | AO20: =AM20-AQ20-AR20 -> 20 | AP20: =AO20*8.4 -> 168 | AQ20: 0 | AR20: 1
A21: 36 | B21: 207669821 | C21: Z24042 | D21: Amit Bar | E21: 2410 | F21: Fulltime Employee | G21: Active | H21: 44528 | J21: 330297 | L21: =J21/12*70% -> 19267.325 | M21: =J21/12*30% -> 8257.425 | N21: =SUM(L21:M21) -> 27524.75 | O21: 15 | P21: =(N21+W21+X21+AA21+T21+R21)*O21% -> 4128.7125 | S21: 315 | V21: 0 | AB21: 154 | AC21: 115 | AD21: 999.1 | AF21: 168.9 | AM21: 21 | AN21: =AM21*8.4 -> 176.4 | AO21: =AM21-AQ21-AR21 -> 7 | AP21: =AO21*8.4 -> 58.8 | AQ21: 14 | AR21: 0
A22: 41 | B22: 204287635 | C22: Z24237 | D22: Shoham Shimon Danino | E22: 2885 | F22: Fulltime Employee | G22: Active | H22: 44577 | J22: 594240 | L22: =J22/12*70% -> 34664 | M22: =J22/12*30% -> 14856 | N22: =SUM(L22:M22) -> 49520 | O22: 15 | P22: =(N22+W22+X22+AA22+T22+R22)*O22% -> 8666.1945 | S22: 315 | V22: 0 | W22: 8254.63 | AB22: 154 | AC22: 115 | AD22: 1000 | AM22: 21 | AN22: =AM22*8.4 -> 176.4 | AO22: =AM22-AQ22-AR22 -> 21 | AP22: =AO22*8.4 -> 176.4 | AQ22: 0 | AR22: 0
A23: 42 | B23: 204596795 | C23: Z24238 | D23: Roi Inbar | E23: 2885 | F23: Fulltime Employee | G23: Active | H23: 44577 | J23: 534600 | L23: =J23/12*70% -> 31185 | M23: =J23/12*30% -> 13365 | N23: =SUM(L23:M23) -> 44550 | O23: 15 | P23: =(N23+W23+X23+AA23+T23+R23)*O23% -> 6682.5 | S23: 315 | V23: 0 | AB23: 154 | AC23: 115 | AD23: 1000 | AM23: 21 | AN23: =AM23*8.4 -> 176.4 | AO23: =AM23-AQ23-AR23 -> 21 | AP23: =AO23*8.4 -> 176.4 | AQ23: 0 | AR23: 0
A24: 43 | B24: 302748843 | C24: Z24239 | D24: Samir Dabit | E24: 2410 | F24: Fulltime Employee | G24: Active | H24: 44581 | J24: 425930 | L24: =J24/12*70% -> 24845.917 | M24: =J24/12*30% -> 10648.25 | N24: =SUM(L24:M24) -> 35494.167 | O24: 0 | P24: =(N24+W24+X24+AA24+T24+R24)*O24% -> 0 | S24: 315 | V24: 0 | AB24: 154 | AC24: 115 | AD24: 1000 | AM24: 21 | AN24: =AM24*8.4 -> 176.4 | AO24: =AM24-AQ24-AR24 -> 21 | AP24: =AO24*8.4 -> 176.4 | AQ24: 0 | AR24: 0
A25: 45 | B25: 305357956 | C25: Z24467 | D25: Noam Yadar | E25: 2410 | F25: Fulltime Employee | G25: Active | H25: 44585 | J25: 489124.9 | L25: =J25/12*70% -> 28532.286 | M25: =J25/12*30% -> 12228.122 | N25: =M25+L25 -> 40760.408 | O25: 15 | P25: =(N25+W25+X25+AA25+T25+R25)*O25% -> 6114.0612 | S25: 315 | V25: 0 | AB25: 154 | AC25: 115 | AD25: 1000 | AM25: 21 | AN25: =AM25*8.4 -> 176.4 | AO25: =AM25-AQ25-AR25 -> 21 | AP25: =AO25*8.4 -> 176.4 | AQ25: 0 | AR25: 0
A26: 47 | B26: 318638038 | C26: Z24243 | D26: Eden Meyuhas | E26: 2885 | F26: Fulltime Employee | G26: Active | H26: 44620 | J26: 528900 | L26: =J26/12*70% -> 30852.5 | M26: =J26/12*30% -> 13222.5 | N26: =SUM(L26:M26) -> 44075 | O26: 15 | P26: =(N26+W26+X26+AA26+T26+R26)*O26% -> 6611.25 | S26: 315 | V26: 0 | AB26: 154 | AC26: 115 | AD26: 1000 | AM26: 21 | AN26: =AM26*8.4 -> 176.4 | AO26: =AM26-AQ26-AR26 -> 19 | AP26: =AO26*8.4 -> 159.6 | AQ26: 2 | AR26: 0 | AU26: 168
A27: 57 | B27: 40678740 | C27: Z25690 | D27: Ricky Levi | E27: 2250 | F27: Fulltime Employee | G27: Active | H27: 44713 | J27: 566000 | L27: =J27/12*70% -> 33016.667 | M27: =J27/12*30% -> 14150 | N27: =SUM(L27:M27) -> 47166.667 | O27: 15 | P27: =(N27+W27+X27+AA27+T27+R27)*O27% -> 7075 | S27: 315 | V27: 0 | AB27: 154 | AC27: 115 | AD27: 1000 | AM27: 21 | AN27: =AM27*8.4 -> 176.4 | AO27: =AM27-AQ27-AR27 -> 21 | AP27: =AO27*8.4 -> 176.4 | AQ27: 0 | AR27: 0 | AU27: 100
A28: 59 | B28: 66729690 | C28: Z25692 | D28: Elad Goren | E28: 2160 | F28: Fulltime Employee | G28: Active | H28: 44713 | J28: 726404 | L28: =J28/12*70% -> 42373.567 | M28: =J28/12*30% -> 18160.1 | N28: =SUM(L28:M28) -> 60533.667 | O28: 15 | P28: =(N28+W28+X28+AA28+T28+R28)*O28% -> 9080.05 | S28: 315 | V28: 150 | AB28: 154 | AC28: 115 | AD28: 1000 | AM28: 21 | AN28: =AM28*8.4 -> 176.4 | AO28: =AM28-AQ28-AR28 -> 21 | AP28: =AO28*8.4 -> 176.4 | AQ28: 0 | AR28: 0
A29: 60 | B29: 323235135 | C29: Z25693 | D29: Dmitry Kulik | E29: 2160 | F29: Fulltime Employee | G29: Active | H29: 44713 | J29: 699998 | L29: =J29/12*70% -> 40833.217 | M29: =J29/12*30% -> 17499.95 | N29: =SUM(L29:M29) -> 58333.167 | O29: 15 | P29: =(N29+W29+X29+AA29+T29+R29)*O29% -> 8749.975 | S29: 315 | V29: 0 | AB29: 154 | AC29: 115 | AD29: 986.52 | AM29: 21 | AN29: =AM29*8.4 -> 176.4 | AO29: =AM29-AQ29-AR29 -> 20 | AP29: =AO29*8.4 -> 168 | AQ29: 1 | AR29: 0
A30: 53 | B30: 304846652 | C30: Z25785 | D30: Dor Pizem | E30: 2410 | F30: Fulltime Employee | G30: Active | H30: 44720 | J30: 497998 | L30: =J30/12*70% -> 29049.883 | M30: =J30/12*30% -> 12449.95 | N30: =SUM(L30:M30) -> 41499.833 | O30: 10 | P30: =(N30+W30+X30+AA30+T30+R30)*O30% -> 4149.9833 | S30: 315 | V30: 0 | AB30: 154 | AC30: 115 | AD30: 999.71 | AM30: 21 | AN30: =AM30*8.4 -> 176.4 | AO30: =AM30-AQ30-AR30 -> 21 | AP30: =AO30*8.4 -> 176.4 | AQ30: 0 | AR30: 0 | AU30: 248
A31: 54 | B31: 321285512 | C31: Z25694 | D31: Vitaly Artemov | E31: 2160 | F31: Fulltime Employee | G31: Active | H31: 44721 | J31: 785030 | L31: =J31/12*70% -> 45793.417 | M31: =J31/12*30% -> 19625.75 | N31: =SUM(L31:M31) -> 65419.167 | O31: 8 | P31: =(N31+W31+X31+AA31+T31+R31)*O31% -> 5233.5333 | S31: 315 | V31: 0 | AB31: 154 | AC31: 115 | AD31: 1000 | AM31: 21 | AN31: =AM31*8.4 -> 176.4 | AO31: =AM31-AQ31-AR31 -> 21 | AP31: =AO31*8.4 -> 176.4 | AQ31: 0 | AR31: 0 | AU31: 70
A32: 55 | B32: 314349622 | C32: Z25730 | D32: Oleg Perah | E32: 2450 | F32: Fulltime Employee | G32: Active | H32: 44735 | J32: 519026 | L32: =J32/12*70% -> 30276.517 | M32: =J32/12*30% -> 12975.65 | N32: =SUM(L32:M32) -> 43252.167 | O32: 15 | P32: =(N32+W32+X32+AA32+T32+R32)*O32% -> 6487.825 | S32: 315 | V32: 0 | AB32: 154 | AC32: 115 | AD32: 1000 | AM32: 21 | AN32: =AM32*8.4 -> 176.4 | AO32: =AM32-AQ32-AR32 -> 21 | AP32: =AO32*8.4 -> 176.4 | AQ32: 0 | AR32: 0
A33: 56 | B33: 309341808 | C33: Z25802 | D33: Marat Khousid | E33: 2160 | F33: Fulltime Employee | G33: Active | H33: 44740 | J33: 791600 | L33: =J33/12*70% -> 46176.667 | M33: =J33/12*30% -> 19790 | N33: =SUM(L33:M33) -> 65966.667 | O33: 7 | P33: =(N33+W33+X33+AA33+T33+R33)*O33% -> 4617.6667 | S33: 315 | V33: 0 | AB33: 154 | AC33: 115 | AD33: 1000 | AM33: 21 | AN33: =AM33*8.4 -> 176.4 | AO33: =AM33-AQ33-AR33 -> 21 | AP33: =AO33*8.4 -> 176.4 | AQ33: 0 | AR33: 0
A34: 61 | B34: 13641527 | C34: Z25922 | D34: Gadi Goldbarg | E34: 2160 | F34: Fulltime Employee | G34: Active | H34: 44752 | J34: 587000 | L34: =J34/12*70% -> 34241.667 | M34: =J34/12*30% -> 14675 | N34: =SUM(L34:M34) -> 48916.667 | O34: 4 | P34: =(N34+W34+X34+AA34+T34+R34)*O34% -> 1956.6667 | S34: 315 | V34: 0 | AB34: 154 | AC34: 115 | AD34: 999.15 | AM34: 21 | AN34: =AM34*8.4 -> 176.4 | AO34: =AM34-AQ34-AR34 -> 21 | AP34: =AO34*8.4 -> 176.4 | AQ34: 0 | AR34: 0
A35: 62 | B35: 15931777 | C35: Z25938 | D35: Amir Tarkey | E35: 2160 | F35: Fulltime Employee | G35: Active | H35: 44759 | J35: 434000 | L35: =J35/12*70% -> 25316.667 | M35: =J35/12*30% -> 10850 | N35: =SUM(L35:M35) -> 36166.667 | O35: 15 | P35: =(N35+W35+X35+AA35+T35+R35)*O35% -> 5425 | S35: 315 | V35: 0 | AB35: 154 | AC35: 115 | AD35: 832.38 | AM35: 21 | AN35: =AM35*8.4 -> 176.4 | AO35: =AM35-AQ35-AR35 -> 21 | AP35: =AO35*8.4 -> 176.4 | AQ35: 0 | AR35: 0
A36: 65 | B36: 333801231 | C36: Z26198 | D36: Jon Joseba Gabilondo Angulo | E36: 2160 | F36: Fulltime Employee | G36: Active | H36: 44774 | J36: 726360 | L36: =J36/12*70% -> 42371 | M36: =J36/12*30% -> 18159 | N36: =SUM(L36:M36) -> 60530 | O36: 10 | P36: =(N36+W36+X36+AA36+T36+R36)*O36% -> 6053 | S36: 315 | V36: 0 | AB36: 154 | AC36: 115 | AD36: 999.5 | AM36: 21 | AN36: =AM36*8.4 -> 176.4 | AO36: =AM36-AQ36-AR36 -> 21 | AP36: =AO36*8.4 -> 176.4 | AQ36: 0 | AR36: 0
A37: 67 | B37: 32105199 | C37: Z26199 | D37: Eyal Lubelski | E37: 2160 | F37: Fulltime Employee | G37: Active | H37: 44774 | J37: 470000 | L37: =J37/12*70% -> 27416.667 | M37: =J37/12*30% -> 11750 | N37: =SUM(L37:M37) -> 39166.667 | O37: 8 | P37: =(N37+W37+X37+AA37+T37+R37)*O37% -> 3133.3333 | S37: 315 | V37: 0 | AB37: 154 | AC37: 115 | AD37: 965 | AM37: 21 | AN37: =AM37*8.4 -> 176.4 | AO37: =AM37-AQ37-AR37 -> 21 | AP37: =AO37*8.4 -> 176.4 | AQ37: 0 | AR37: 0
A38: 68 | B38: 34890491 | C38: Z26200 | D38: Bar Zukerman | E38: 2160 | F38: Fulltime Employee | G38: Active | H38: 44780 | J38: 634800 | L38: =J38/12*70% -> 37030 | M38: =J38/12*30% -> 15870 | N38: =SUM(L38:M38) -> 52900 | O38: 10 | P38: =(N38+W38+X38+AA38+T38+R38)*O38% -> 5290 | S38: 315 | V38: 0 | AB38: 154 | AC38: 115 | AD38: 1000 | AM38: 21 | AN38: =AM38*8.4 -> 176.4 | AO38: =AM38-AQ38-AR38 -> 21 | AP38: =AO38*8.4 -> 176.4 | AQ38: 0 | AR38: 0
A39: 69 | B39: 304603590 | C39: Z26424 | D39: Alexander Jouravski | E39: 2160 | F39: Fulltime Employee | G39: Active | H39: 44794 | J39: 648240 | L39: =J39/12*70% -> 37814 | M39: =J39/12*30% -> 16206 | N39: =SUM(L39:M39) -> 54020 | O39: 15 | P39: =(N39+W39+X39+AA39+T39+R39)*O39% -> 8103 | S39: 315 | V39: 0 | AB39: 154 | AC39: 115 | AD39: 1000 | AM39: 21 | AN39: =AM39*8.4 -> 176.4 | AO39: =AM39-AQ39-AR39 -> 21 | AP39: =AO39*8.4 -> 176.4 | AQ39: 0 | AR39: 0
A40: 76 | B40: 39076492 | C40: Z26527 | D40: Roi Zentner | E40: 2885 | F40: Fulltime Employee | G40: Active | H40: 44805 | J40: 551655 | L40: =J40/12*70% -> 32179.875 | M40: =J40/12*30% -> 13791.375 | N40: =SUM(L40:M40) -> 45971.25 | O40: 15 | P40: =(N40+W40+X40+AA40+T40+R40)*O40% -> 6895.6875 | S40: 315 | V40: 0 | AB40: 154 | AC40: 115 | AD40: 985.3 | AM40: 21 | AN40: =AM40*8.4 -> 176.4 | AO40: =AM40-AQ40-AR40 -> 20 | AP40: =AO40*8.4 -> 168 | AQ40: 1 | AR40: 0 | AU40: 350
...

Sheet System
A1: שם החברה | B1: שנת מס | C1: מספר עובד | D1: שם העובד | E1: מספר חודש | F1: מספר רכיב | G1: שם רכיב שכר | H1: סיכום ברוטו | I1: סיכום כמות | J1: שם מחלקה
A2: זיסקיילר ישראל בע"מ | B2: 2025 | C2: 4 | D2: גלדין לאוניד | E2: 11 | F2: 1 | G2: משכורת | H2: 36763.43 | I2: 0 | J2: R&D
A3: זיסקיילר ישראל בע"מ | B3: 2025 | C3: 4 | D3: גלדין לאוניד | E3: 11 | F3: 3 | G3: טלפון | H3: 230 | I3: 0 | J3: R&D
A4: זיסקיילר ישראל בע"מ | B4: 2025 | C4: 4 | D4: גלדין לאוניד | E4: 11 | F4: 4 | G4: נסיעות | H4: 315 | I4: 0 | J4: R&D
A5: זיסקיילר ישראל בע"מ | B5: 2025 | C5: 4 | D5: גלדין לאוניד | E5: 11 | F5: 6 | G5: ש.נ גלובליות | H5: 15755.76 | I5: 0 | J5: R&D
A6: זיסקיילר ישראל בע"מ | B6: 2025 | C6: 4 | D6: גלדין לאוניד | E6: 11 | F6: 24 | G6: שווי ארוחות | H6: 1000 | I6: 0 | J6: R&D
A7: זיסקיילר ישראל בע"מ | B7: 2025 | C7: 4 | D7: גלדין לאוניד | E7: 11 | F7: 25 | G7: פיצוי שווי | H7: 154 | I7: 0 | J7: R&D
A8: זיסקיילר ישראל בע"מ | B8: 2025 | C8: 4 | D8: גלדין לאוניד | E8: 11 | F8: 51 | G8: שווי ביטוח בריאות | H8: 154 | I8: 0 | J8: R&D
A9: זיסקיילר ישראל בע"מ | B9: 2025 | C9: 4 | D9: גלדין לאוניד | E9: 11 | F9: 93 | G9: זק.תגמולים | H9: 1616.85 | I9: 0 | J9: R&D
A10: זיסקיילר ישראל בע"מ | B10: 2025 | C10: 6 | D10: פוזמנטיר נדב | E10: 11 | F10: 1 | G10: משכורת | H10: 36458.74 | I10: 0 | J10: R&D
A11: זיסקיילר ישראל בע"מ | B11: 2025 | C11: 6 | D11: פוזמנטיר נדב | E11: 11 | F11: 3 | G11: טלפון | H11: 230 | I11: 0 | J11: R&D
A12: זיסקיילר ישראל בע"מ | B12: 2025 | C12: 6 | D12: פוזמנטיר נדב | E12: 11 | F12: 4 | G12: נסיעות | H12: 315 | I12: 0 | J12: R&D
A13: זיסקיילר ישראל בע"מ | B13: 2025 | C13: 6 | D13: פוזמנטיר נדב | E13: 11 | F13: 6 | G13: ש.נ גלובליות | H13: 15625.18 | I13: 0 | J13: R&D
... A804: זיסקיילר ישראל בע"מ | B804: 2025 | C804: 139 | D804: סולר ליאת | E804: 11 | F804: 51 | G804: שווי ביטוח בריאות | H804: 154 | I804: 0 | J804: customer success

Sheet Deductions
A1: שם החברה | B1: שנת מס | C1: מספר עובד | D1: שם העובד | E1: שם מחלקה | F1: מספר חודש | G1: מספר שורה | H1: מספר ניכוי | I1: קוד סוג ניכוי | J1: שם הניכוי | K1: סכום הניכוי
A2: זיסקיילר ישראל בע"מ | B2: 2025 | C2: 4 | D2: גלדין לאוניד | E2: R&D | F2: 11 | G2: 0 | H2: 8 | I2: ש | J2: מקד' אופצ' | K2: 7877.88
A3: זיסקיילר ישראל בע"מ | B3: 2025 | C3: 4 | D3: גלדין לאוניד | E3: R&D | F3: 11 | G3: 1 | H3: 9 | I3: ש | J3: החזר הוצ' | K3: -1580
A4: זיסקיילר ישראל בע"מ | B4: 2025 | C4: 6 | D4: פוזמנטיר נדב | E4: R&D | F4: 11 | G4: 0 | H4: 8 | I4: ש | J4: מקד' אופצ' | K4: 7812.59
A5: זיסקיילר ישראל בע"מ | B5: 2025 | C5: 8 | D5: כץ עידו | E5: R&D | F5: 11 | G5: 0 | H5: 8 | I5: ש | J5: מקד' אופצ' | K5: 7650.03
A6: זיסקיילר ישראל בע"מ | B6: 2025 | C6: 8 | D6: כץ עידו | E6: R&D | F6: 11 | G6: 1 | H6: 9 | I6: ש | J6: החזר הוצ' | K6: -1860
A7: זיסקיילר ישראל בע"מ | B7: 2025 | C7: 11 | D7: קולברג אלעד | E7: R&D | F7: 11 | G7: 0 | H7: 8 | I7: ש | J7: מקד' אופצ' | K7: 6126.68
A8: זיסקיילר ישראל בע"מ | B8: 2025 | C8: 12 | D8: נמצוב אריאל חיים | E8: R&D | F8: 11 | G8: 0 | H8: 8 | I8: ש | J8: מקד' אופצ' | K8: 6944.14
A9: זיסקיילר ישראל בע"מ | B9: 2025 | C9: 12 | D9: נמצוב אריאל חיים | E9: R&D | F9: 11 | G9: 1 | H9: 9 | I9: ש | J9: החזר הוצ' | K9: -391
A10: זיסקיילר ישראל בע"מ | B10: 2025 | C10: 14 | D10: סבג דני | E10: R&D | F10: 11 | G10: 0 | H10: 8 | I10: ש | J10: מקד' אופצ' | K10: 3643.67
A11: זיסקיילר ישראל בע"מ | B11: 2025 | C11: 14 | D11: סבג דני | E11: R&D | F11: 11 | G11: 1 | H11: 9 | I11: ש | J11: החזר הוצ' | K11: -208
A12: זיסקיילר ישראל בע"מ | B12: 2025 | C12: 14 | D12: סבג דני | E12: R&D | F12: 11 | G12: 2 | H12: 13 | I12: ש | J12: מניות | K12: -77367.45
A13: זיסקיילר ישראל בע"מ | B13: 2025 | C13: 14 | D13: סבג דני | E13: R&D | F13: 11 | G13: 3 | H13: 13 | I13: ש | J13: מניות | K13: -54557.91
... A151: זיסקיילר ישראל בע"מ | B151: 2025 | C151: 137 | D151: קסטל גיא | E151: R&D | F151: 11 | G151: 0 | H151: 9 | I151: ש | J151: החזר הוצ' | K151: -53.9

Sheet SBC
A1: Employee Name | B1: Type | C1: ID | D1: Exercise Date | E1: Grant Date | F1: Net gain | G1: C.RATE | H1: NetGain ILS | I1: Marginal Tax rate | J1: Capital Gain Tax Rate | K1: Marginal Income | L1: Marginal Tax | M1: Capital Gain Income | N1: Capital Tax | O1: Advance payment for tax deduction | P1: Company | Q1: Z.ID | R1: תאריך עיזבה
A2: Aboudy, Omer Alon | B2: ESPP | C2: 206963159 | D2: 45960 | E2: 45460 | F2: 5565.8513 | G2: 3.2348 | H2: =F2*G2 -> 18004.416 | I2: 0.6217 | J2: 0.3 | K2: 18004.416 | L2: =I2*K2 -> 11193.345 | M2: 0 | N2: =M2*J2 -> 0 | O2: 11193.345 | P2: ZSCALER | Q2: Z30392 | R2: 0
A3: Aboudy, Omer Alon | B3: ESPP | C3: 206963159 | D3: 45960 | E3: 45642 | F3: 4606.2218 | G3: 3.2348 | H3: =F3*G3 -> 14900.206 | I3: 0.6217 | J3: 0.3 | K3: 14900.206 | L3: =I3*K3 -> 9263.4582 | M3: 0 | N3: =M3*J3 -> 0 | O3: 9263.4582 | P3: ZSCALER | Q3: Z30392 | R3: 0
A4: Aharon, Oded | B4: RSU | C4: 32949166 | D4: 45943 | E4: 45551 | F4: 4391.9658 | G4: 3.276 | H4: 14388.08 | I4: 0.6217 | J4: 0.3 | K4: 14388.08 | L4: =I4*K4 -> 8945.0694 | M4: 0 | N4: =M4*J4 -> 0 | O4: 8945.0694 | P4: ZSCALER | Q4: Z28055 | R4: 0
A5: Almaz, Assaf | B5: RSU | C5: 28831709 | D5: 45953 | E5: 45043 | F5: 18759.358 | G5: 3.2348 | H5: 60682.77 | I5: 0.6217 | J5: 0.3 | K5: 20911.833 | L5: =I5*K5 -> 13000.887 | M5: 39770.937 | N5: =M5*J5 -> 11931.281 | O5: 24932.168 | P5: ZSCALER | Q5: Z26533 | R5: 0
A6: Almaz, Assaf | B6: RSU | C6: 28831709 | D6: 45953 | E6: 45043 | F6: 18759.358 | G6: 3.2348 | H6: 60682.77 | I6: 0.6217 | J6: 0.3 | K6: 20911.833 | L6: =I6*K6 -> 13000.887 | M6: 39770.937 | N6: =M6*J6 -> 11931.281 | O6: 24932.168 | P6: ZSCALER | Q6: Z26533 | R6: 0
A7: Almaz, Assaf | B7: RSU | C7: 28831709 | D7: 45954 | E7: 44894 | F7: 133599.89 | G7: 3.2262 | H7: 431019.98 | I7: 0.6217 | J7: 0.3 | K7: 186804.61 | L7: =I7*K7 -> 116136.42 | M7: 244215.37 | N7: =M7*J7 -> 73264.612 | O7: 189401.04 | P7: ZSCALER | Q7: Z26533 | R7: 0
A8: Almaz, Assaf | B8: RSU | C8: 28831709 | D8: 45954 | E8: 45177 | F8: 24261.482 | G8: 3.2262 | H8: 78272.394 | I8: 0.6217 | J8: 0.3 | K8: 35666.632 | L8: =I8*K8 -> 22173.945 | M8: 42605.761 | N8: =M8*J8 -> 12781.728 | O8: 34955.674 | P8: ZSCALER | Q8: Z26533 | R8: 0
A9: Almaz, Assaf | B9: RSU | C9: 28831709 | D9: 45954 | E9: 45043 | F9: 19732.672 | G9: 3.2262 | H9: 63661.547 | I9: 0.6217 | J9: 0.3 | K9: 20852.493 | L9: =I9*K9 -> 12963.995 | M9: 42809.053 | N9: =M9*J9 -> 12842.716 | O9: 25806.711 | P9: ZSCALER | Q9: Z26533 | R9: 0
A10: Almaz, Assaf | B10: RSU | C10: 28831709 | D10: 45954 | E10: 44894 | F10: 133599.89 | G10: 3.2262 | H10: 431019.98 | I10: 0.6217 | J10: 0.3 | K10: 186804.61 | L10: =I10*K10 -> 116136.42 | M10: 244215.37 | N10: =M10*J10 -> 73264.612 | O10: 189401.04 | P10: ZSCALER | Q10: Z26533 | R10: 0
A11: Almaz, Assaf | B11: RSU | C11: 28831709 | D11: 45954 | E11: 45177 | F11: 24584.969 | G11: 3.2262 | H11: 79316.025 | I11: 0.6217 | J11: 0.3 | K11: 36142.187 | L11: =I11*K11 -> 22469.598 | M11: 43173.838 | N11: =M11*J11 -> 12952.151 | O11: 35421.749 | P11: ZSCALER | Q11: Z26533 | R11: 0
A12: Almaz, Assaf | B12: RSU | C12: 28831709 | D12: 45954 | E12: 45043 | F12: 19732.672 | G12: 3.2262 | H12: 63661.547 | I12: 0.6217 | J12: 0.3 | K12: 20852.493 | L12: =I12*K12 -> 12963.995 | M12: 42809.053 | N12: =M12*J12 -> 12842.716 | O12: 25806.711 | P12: ZSCALER | Q12: Z26533 | R12: 0
A13: Almaz, Assaf | B13: RSU | C13: 28831709 | D13: 45954 | E13: 44894 | F13: 133923.38 | G13: 3.2262 | H13: 432063.61 | I13: 0.6217 | J13: 0.3 | K13: 187256.92 | L13: =I13*K13 -> 116417.63 | M13: 244806.69 | N13: =M13*J13 -> 73442.008 | O13: 189859.63 | P13: ZSCALER | Q13: Z26533 | R13: 0
A14: Almaz, Assaf | B14: ESPP | C14: 28831709 | D14: 45954 | E14: 45275 | F14: 13874.942 | G14: 3.2262 | H14: =F14*G14 -> 44763.337 | I14: 0.6217 | J14: 0.3 | K14: 44763.337 | L14: =I14*K14 -> 27829.367 | M14: 0 | N14: =M14*J14 -> 0 | O14: 27829.367 | P14: ZSCALER | Q14: Z26533 | R14: 0
A15: Artemov, Vitaly | B15: RSU | C15: 321285512 | D15: 45957 | E15: 45177 | F15: 13975.047 | G15: 3.2292 | H15: 45128.223 | I15: 0.6217 | J15: 0.3 | K15: 20466.45 | L15: =I15*K15 -> 12723.992 | M15: 24661.773 | N15: =M15*J15 -> 7398.5318 | O15: 20122.524 | P15: ZSCALER | Q15: Z25694 | R15: 0
A16: Artemov, Vitaly | B16: RSU | C16: 321285512 | D16: 45957 | E16: 44753 | F16: 41925.142 | G16: 3.2292 | H16: 135384.67 | I16: 0.6217 | J16: 0.3 | K16: 64268.106 | L16: =I16*K16 -> 39955.482 | M16: 71116.562 | N16: =M16*J16 -> 21334.969 | O16: 61290.45 | P16: ZSCALER | Q16: Z25694 | R16: 0
A17: Artemov, Vitaly | B17: RSU | C17: 321285512 | D17: 45957 | E17: 45177 | F17: 13975.047 | G17: 3.2292 | H17: 45128.223 | I17: 0.6217 | J17: 0.3 | K17: 20466.45 | L17: =I17*K17 -> 12723.992 | M17: 24661.773 | N17: =M17*J17 -> 7398.5318 | O17: 20122.524 | P17: ZSCALER | Q17: Z25694 | R17: 0
A18: Artemov, Vitaly | B18: RSU | C18: 321285512 | D18: 45957 | E18: 45177 | F18: 13975.047 | G18: 3.2292 | H18: 45128.223 | I18: 0.6217 | J18: 0.3 | K18: 20466.45 | L18: =I18*K18 -> 12723.992 | M18: 24661.773 | N18: =M18*J18 -> 7398.5318 | O18: 20122.524 | P18: ZSCALER | Q18: Z25694 | R18: 0
A19: Artemov, Vitaly | B19: RSU | C19: 321285512 | D19: 45957 | E19: 45177 | F19: 13975.047 | G19: 3.2292 | H19: 45128.223 | I19: 0.6217 | J19: 0.3 | K19: 20466.45 | L19: =I19*K19 -> 12723.992 | M19: 24661.773 | N19: =M19*J19 -> 7398.5318 | O19: 20122.524 | P19: ZSCALER | Q19: Z25694 | R19: 0
A20: Artemov, Vitaly | B20: RSU | C20: 321285512 | D20: 45957 | E20: 45177 | F20: 14300.048 | G20: 3.2292 | H20: 46177.716 | I20: 0.6217 | J20: 0.3 | K20: 20942.414 | L20: =I20*K20 -> 13019.899 | M20: 25235.302 | N20: =M20*J20 -> 7570.5907 | O20: 20590.49 | P20: ZSCALER | Q20: Z25694 | R20: 0
A21: Artemov, Vitaly | B21: RSU | C21: 321285512 | D21: 45957 | E21: 45177 | F21: 13975.047 | G21: 3.2292 | H21: 45128.223 | I21: 0.6217 | J21: 0.3 | K21: 20466.45 | L21: =I21*K21 -> 12723.992 | M21: 24661.773 | N21: =M21*J21 -> 7398.5318 | O21: 20122.524 | P21: ZSCALER | Q21: Z25694 | R21: 0
A22: Artemov, Vitaly | B22: RSU | C22: 321285512 | D22: 45957 | E22: 45177 | F22: 14300.048 | G22: 3.2292 | H22: 46177.716 | I22: 0.6217 | J22: 0.3 | K22: 20942.414 | L22: =I22*K22 -> 13019.899 | M22: 25235.302 | N22: =M22*J22 -> 7570.5907 | O22: 20590.49 | P22: ZSCALER | Q22: Z25694 | R22: 0
A23: Artemov, Vitaly | B23: RSU | C23: 321285512 | D23: 45957 | E23: 45177 | F23: 13975.047 | G23: 3.2292 | H23: 45128.223 | I23: 0.6217 | J23: 0.3 | K23: 20466.45 | L23: =I23*K23 -> 12723.992 | M23: 24661.773 | N23: =M23*J23 -> 7398.5318 | O23: 20122.524 | P23: ZSCALER | Q23: Z25694 | R23: 0
A24: Artemov, Vitaly | B24: RSU | C24: 321285512 | D24: 45957 | E24: 45043 | F24: 12025.041 | G24: 3.2292 | H24: 38831.261 | I24: 0.6217 | J24: 0.3 | K24: 12658.761 | L24: =I24*K24 -> 7869.9518 | M24: 26172.5 | N24: =M24*J24 -> 7851.7501 | O24: 15721.702 | P24: ZSCALER | Q24: Z25694 | R24: 0
A25: Assayag, Jonathan | B25: RSU | C25: 207763806 | D25: 45954 | E25: 45177 | F25: 7059.697 | G25: 3.2262 | H25: 22775.995 | I25: 0.6217 | J25: 0.3 | K25: 10462.488 | L25: =I25*K25 -> 6504.529 | M25: 12313.506 | N25: =M25*J25 -> 3694.0519 | O25: 10198.581 | P25: ZSCALER | Q25: Z23077 | R25: 0
A26: Assayag, Jonathan | B26: RSU | C26: 207763806 | D26: 45954 | E26: 44537 | F26: 7380.5924 | G26: 3.2262 | H26: 23811.267 | I26: 0.6217 | J26: 0.3 | K26: 23811.267 | L26: =I26*K26 -> 14803.465 | M26: 0 | N26: =M26*J26 -> 0 | O26: 14803.465 | P26: ZSCALER | Q26: Z23077 | R26: 0
... A115: Meyuhas, Eden | B115: RSU | C115: 318638038 | D115: 45957 | E115: 44630 | F115: 12686.725 | G115: 3.2292 | H115: 40967.974 | I115: 0.6217 | J115: 0.3 | K115: 31429.789 | L115: =I115*K115 -> 19539.9 | M115: 9538.1848 | N115: =M115*J115 -> 2861.4554 | O115: 22401.355 | P115: ZSCALER | Q115: Z24243 | R115: 0
A116: Oren, Sela Ari | B116: ESPP | C116: 201179025 | D116: 45939 | E116: 45824 | F116: 3269.8783 | G116: 3.276 | H116: =F116*G116 -> 10712.121 | I116: 0.6217 | J116: 0.3 | K116: 10712.121 | L116: =I116*K116 -> 6659.7258 | M116: 0 | N116: =M116*J116 -> 0 | O116: 6659.7258 | P116: ZSCALER | Q116: Z32650 | R116: 0
A117: Oren, Sela Ari | B117: ESPP | C117: 201179025 | D117: 45958 | E117: 45824 | F117: 3434.8042 | G117: 3.2348 | H117: =F117*G117 -> 11110.905 | I117: 0.6217 | J117: 0.3 | K117: 11110.905 | L117: =I117*K117 -> 6907.6494 | M117: 0 | N117: =M117*J117 -> 0 | O117: 6907.6494 | P117: ZSCALER | Q117: Z32650 | R117: 0
A118: Perah, Oleg | B118: RSU | C118: 314349622 | D118: 45932 | E118: 45177 | F118: 3360.8682 | G118: 3.2611 | H118: 10960.127 | I118: 0.6217 | J118: 0.3 | K118: 5288.4854 | L118: =I118*K118 -> 3287.8514 | M118: 5671.642 | N118: =M118*J118 -> 1701.4926 | O118: 4989.344 | P118: ZSCALER | Q118: Z25730 | R118: 0
A119: Perah, Oleg | B119: RSU | C119: 314349622 | D119: 45932 | E119: 44753 | F119: 19859.676 | G119: 3.2611 | H119: 64764.389 | I119: 0.6217 | J119: 0.3 | K119: 32709.917 | L119: =I119*K119 -> 20335.756 | M119: 32054.472 | N119: =M119*J119 -> 9616.3415 | O119: 29952.097 | P119: ZSCALER | Q119: Z25730 | R119: 0
A120: Perah, Oleg | B120: RSU | C120: 314349622 | D120: 45932 | E120: 44753 | F120: 19859.676 | G120: 3.2611 | H120: 64764.389 | I120: 0.6217 | J120: 0.3 | K120: 32709.917 | L120: =I120*K120 -> 20335.756 | M120: 32054.472 | N120: =M120*J120 -> 9616.3415 | O120: 29952.097 | P120: ZSCALER | Q120: Z25730 | R120: 0
A121: Perah, Oleg | B121: RSU | C121: 314349622 | D121: 45932 | E121: 45177 | F121: 3666.4017 | G121: 3.2611 | H121: 11956.503 | I121: 0.6217 | J121: 0.3 | K121: 5769.2568 | L121: =I121*K121 -> 3586.7469 | M121: 6187.2458 | N121: =M121*J121 -> 1856.1738 | O121: 5442.9207 | P121: ZSCALER | Q121: Z25730 | R121: 0
A122: Perah, Oleg | B122: RSU | C122: 314349622 | D122: 45932 | E122: 45177 | F122: 3666.4017 | G122: 3.2611 | H122: 11956.503 | I122: 0.6217 | J122: 0.3 | K122: 5769.2568 | L122: =I122*K122 -> 3586.7469 | M122: 6187.2458 | N122: =M122*J122 -> 1856.1738 | O122: 5442.9207 | P122: ZSCALER | Q122: Z25730 | R122: 0
A123: Perah, Oleg | B123: RSU | C123: 314349622 | D123: 45932 | E123: 45177 | F123: 3666.4017 | G123: 3.2611 | H123: 11956.503 | I123: 0.6217 | J123: 0.3 | K123: 5769.2568 | L123: =I123*K123 -> 3586.7469 | M123: 6187.2458 | N123: =M123*J123 -> 1856.1738 | O123: 5442.9207 | P123: ZSCALER | Q123: Z25730 | R123: 0
A124: Perah, Oleg | B124: RSU | C124: 314349622 | D124: 45932 | E124: 44753 | F124: 19859.676 | G124: 3.2611 | H124: 64764.389 | I124: 0.6217 | J124: 0.3 | K124: 32709.917 | L124: =I124*K124 -> 20335.756 | M124: 32054.472 | N124: =M124*J124 -> 9616.3415 | O124: 29952.097 | P124: ZSCALER | Q124: Z25730 | R124: 0
A125: Perah, Oleg | B125: RSU | C125: 314349622 | D125: 45932 | E125: 44753 | F125: 19859.676 | G125: 3.2611 | H125: 64764.389 | I125: 0.6217 | J125: 0.3 | K125: 32709.917 | L125: =I125*K125 -> 20335.756 | M125: 32054.472 | N125: =M125*J125 -> 9616.3415 | O125: 29952.097 | P125: ZSCALER | Q125: Z25730 | R125: 0
A126: Perah, Oleg | B126: RSU | C126: 314349622 | D126: 45932 | E126: 44753 | F126: 19859.676 | G126: 3.2611 | H126: 64764.389 | I126: 0.6217 | J126: 0.3 | K126: 32709.917 | L126: =I126*K126 -> 20335.756 | M126: 32054.472 | N126: =M126*J126 -> 9616.3415 | O126: 29952.097 | P126: ZSCALER | Q126: Z25730 | R126: 0
A127: Perah, Oleg | B127: RSU | C127: 314349622 | D127: 45932 | E127: 45177 | F127: 3666.4017 | G127: 3.2611 | H127: 11956.503 | I127: 0.6217 | J127: 0.3 | K127: 5769.2568 | L127: =I127*K127 -> 3586.7469 | M127: 6187.2458 | N127: =M127*J127 -> 1856.1738 | O127: 5442.9207 | P127: ZSCALER | Q127: Z25730 | R127: 0
A128: Perah, Oleg | B128: RSU | C128: 314349622 | D128: 45932 | E128: 45043 | F128: 4583.0021 | G128: 3.2611 | H128: 14945.628 | I128: 0.6217 | J128: 0.3 | K128: 5184.2102 | L128: =I128*K128 -> 3223.0235 | M128: 9761.418 | N128: =M128*J128 -> 2928.4254 | O128: 6151.4489 | P128: ZSCALER | Q128: Z25730 | R128: 0
...

Sheet Link
A1: בס"ד
C2: עמודת קוד עובד | D2: =Client!A1 -> No. | F2: קוד עובד במערכת | G2: =System!C1 -> מספר עובד | I2: קוד עובד | J2: מספר עובד | N2: מס תז בקובץ SBC | O2: ID
C3: שם במערכת | D3: =Client!D1 -> Employee's name | F3: קוד רכיב במערכת | G3: =System!F1 -> מספר רכיב | I3: עמודת קוד | J3: מספר ניכוי | N3: מס תז בקובץ הלקוח | O3: ID
C4: הפרש זניח בסכומים | D4: 0.0055 | F4: שם רכיב במערכת | G4: =System!G1 -> שם רכיב שכר | I4: עמודת שם ניכוי | J4: שם הניכוי | N4: סוג המרכיב | O4: Type
F5: סכום במערכת | G5: =System!H1 -> סיכום ברוטו | I5: עמודת סכום | J5: סכום הניכוי
C7: רשימת קודים בקובץ לקוח | F7: רשימת קודי שכר לא לבדיקה | I7: התאמת ניכויים - רשימת קודים בקובץ לקוח | M7: התאמת רכיבי SBC לרכיבי שכר וניכויים
C8: ItemName | D8: Code | F8: Code | G8: ItemName | I8: ItemName | J8: Code | K8: Sign | M8: InsType | N8: Col | O8: Deductions | P8: System
C9: Salary | D9: 1 | F9: 25 | G9: =VLOOKUP(F9,System!F:G,2,0) -> פיצוי שווי | I9: ESPP Contribution - Amount | J9: 8 | K9: 1 | M9: RSU | N9: Marginal Income | P9: 15
C10: Global overtime | D10: 6 | F10: 91 | G10: =VLOOKUP(F10,System!F:G,2,0) -> זק.השתלמות | I10: Reimbursement | J10: 9 | K10: -1 | M10: RSU | N10: Marginal Tax | O10: 13
C11: BIK - Mobile Reimbursment - to be grossed up | D11: 3 | F11: 93 | G11: =VLOOKUP(F11,System!F:G,2,0) -> זק.תגמולים | M11: RSU | N11: Capital Gain Income | P11: 62
C12: Travel Allowance | D12: 4 | F12: 15 | G12: =VLOOKUP(F12,System!F:G,2,0) -> שווי מניות פירותי | M12: RSU | N12: Capital Tax | O12: 13
F13: 62 | G13: =VLOOKUP(F13,System!F:G,2,0) -> שווי מניות הוני 25%
C14: Phone value | D14: 5 | G14: =VLOOKUP(F14,System!F:G,2,0) -> #N/A | M14: ESPP | N14: Marginal Income | P14: 61
C15: BIK- Birthday Gift (to be grossed up) | D15: 22 | G15: =VLOOKUP(F15,System!F:G,2,0) -> #N/A | M15: ESPP | N15: Marginal Tax | O15: 16
C16: Referral Bonus | D16: 9 | G16: =VLOOKUP(F16,System!F:G,2,0) -> #N/A | M16: ESPP | N16: Capital Gain Income | P16: 75
C17: BIK Health Insurance (to be grossed up) | D17: 51 | G17: =VLOOKUP(F17,System!F:G,2,0) -> #N/A | M17: ESPP | N17: Capital Tax | O17: 16
C18: BIK - Mobile Reimbursment - to be grossed up | D18: 24 | G18: =VLOOKUP(F18,System!F:G,2,0) -> #N/A
C19: BIK - Meals - October 2025 (EE bears the tax) | D19: 24 | G19: =VLOOKUP(F19,System!F:G,2,0) -> #N/A
C20: BIK Lunch Meals- (to be grossed up) October 2025 | D20: 24 | G20: =VLOOKUP(F20,System!F:G,2,0) -> #N/A
C21: BIK Dinner Meals- (to be grossed up) October 2025 | D21: 24 | G21: =VLOOKUP(F21,System!F:G,2,0) -> #N/A
G22: =VLOOKUP(F22,System!F:G,2,0) -> #N/A
G23: =VLOOKUP(F23,System!F:G,2,0) -> #N/A
G24: =VLOOKUP(F24,System!F:G,2,0) -> #N/A

Sheet Payroll_Findings
A1: {=_xlfn._xlws.PY(0,0,EmpID,EmpName,SysEmpID,SysCode,SysItemName,SysValue,MinDiff,ClientData,SystemData,Codes,IgnoreCodes)} -> No. | B1: Employee's name | C1: Code | D1: value | E1: מספר עובד | F1: מספר רכיב | G1: שם רכיב שכר | H1: סיכום ברוטו
A2: 4 | B2: Leonid Geldin | C2: 3 | D2: 115 | E2: 4 | F2: 3 | G2: טלפון | H2: 230
A3: 4 | B3: Leonid Geldin | C3: 24 | D3: 1115 | E3: 4 | F3: 24 | G3: שווי ארוחות | H3: 1000
A4: 6 | B4: Nadav Pozmantir | C4: 3 | D4: 115 | E4: 6 | F4: 3 | G4: טלפון | H4: 230
A5: 6 | B5: Nadav Pozmantir | C5: 24 | D5: 1115 | E5: 6 | F5: 24 | G5: שווי ארוחות | H5: 1000
A6: 8 | B6: Ido Katz | C6: 3 | D6: 115 | E6: 8 | F6: 3 | G6: טלפון | H6: 230
A7: 8 | B7: Ido Katz | C7: 24 | D7: 1115 | E7: 8 | F7: 24 | G7: שווי ארוחות | H7: 1000
A8: 11 | B8: Elad Kolberg | C8: 3 | D8: 115 | E8: 11 | F8: 3 | G8: טלפון | H8: 230
A9: 11 | B9: Elad Kolberg | C9: 24 | D9: 1115 | E9: 11 | F9: 24 | G9: שווי ארוחות | H9: 1000
A10: 12 | B10: Ariel Nemtzov | C10: 3 | D10: 115 | E10: 12 | F10: 3 | G10: טלפון | H10: 281.12
A11: 12 | B11: Ariel Nemtzov | C11: 24 | D11: 1115 | E11: 12 | F11: 24 | G11: שווי ארוחות | H11: 1000
A12: 14 | B12: Danny Sabag | C12: 3 | D12: 115 | E12: 14 | F12: 3 | G12: טלפון | H12: 304.03
A13: 14 | B13: Danny Sabag | C13: 24 | D13: 1114.96 | E13: 14 | F13: 24 | G13: שווי ארוחות | H13: 999.96
... A15: 15 | B15: Oz Molaim | C15: 4 | D15: 315 | E15: 15 | F15: 4 | G15: נסיעות | H15: 452
A16: 0 | B16: 0 | C16: 0 | D16: 0 | E16: 15 | F16: 14 | G16: תשלום הפרש מילואים | H16: 4957.79
A17: 15 | B17: Oz Molaim | C17: 24 | D17: 1055.5 | E17: 15 | F17: 24 | G17: שווי ארוחות | H17: 940.5
A18: 16 | B18: Maya Zax | C18: 3 | D18: 115 | E18: 16 | F18: 3 | G18: טלפון | H18: 218.47
A19: 16 | B19: Maya Zax | C19: 24 | D19: 815 | E19: 16 | F19: 24 | G19: שווי ארוחות | H19: 700
A20: 17 | B20: Adi Adrai | C20: 3 | D20: 115 | E20: 17 | F20: 3 | G20: טלפון | H20: 230
A21: 17 | B21: Adi Adrai | C21: 24 | D21: 853 | E21: 17 | F21: 24 | G21: שווי ארוחות | H21: 738
A22: 21 | B22: Esther Shteinberg | C22: 3 | D22: 115 | E22: 21 | F22: 3 | G22: טלפון | H22: 303.97
A23: 21 | B23: Esther Shteinberg | C23: 24 | D23: 1115 | E23: 21 | F23: 24 | G23: שווי ארוחות | H23: 1000
A24: 22 | B24: Adam Hudeda | C24: 3 | D24: 115 | E24: 22 | F24: 3 | G24: טלפון | H24: 303.98
A25: 22 | B25: Adam Hudeda | C25: 4 | D25: 315 | E25: 22 | F25: 4 | G25: נסיעות | H25: 452
A26: 22 | B26: Adam Hudeda | C26: 24 | D26: 1115 | E26: 22 | F26: 24 | G26: שווי ארוחות | H26: 1000
A27: 23 | B27: Ofer Yarom | C27: 3 | D27: 115 | E27: 23 | F27: 3 | G27: טלפון | H27: 230
A28: 23 | B28: Ofer Yarom | C28: 24 | D28: 1110.72 | E28: 23 | F28: 24 | G28: שווי ארוחות | H28: 995.72
... A31: 26 | B31: Dani Rubin | C31: 3 | D31: 115 | E31: 26 | F31: 3 | G31: טלפון | H31: 304
A32: 0 | B32: 0 | C32: 0 | D32: 0 | E32: 26 | F32: 14 | G32: תשלום הפרש מילואים | H32: 2308
A33: 26 | B33: Dani Rubin | C33: 24 | D33: 1115 | E33: 26 | F33: 24 | G33: שווי ארוחות | H33: 1000
A34: 27 | B34: Jonathan Assayag | C34: 3 | D34: 115 | E34: 27 | F34: 3 | G34: טלפון | H34: 303.97
A35: 0 | B35: 0 | C35: 0 | D35: 0 | E35: 27 | F35: 14 | G35: תשלום הפרש מילואים | H35: 1690
A36: 27 | B36: Jonathan Assayag | C36: 24 | D36: 1115 | E36: 27 | F36: 24 | G36: שווי ארוחות | H36: 1000
A37: 28 | B37: Tamir Leshetz | C37: 3 | D37: 115 | E37: 28 | F37: 3 | G37: טלפון | H37: 283.01
A38: 28 | B38: Tamir Leshetz | C38: 24 | D38: 1115 | E38: 28 | F38: 24 | G38: שווי ארוחות | H38: 1000
A39: 30 | B39: Gal Shvinkelstein | C39: 3 | D39: 115 | E39: 30 | F39: 3 | G39: טלפון | H39: 304
A40: 30 | B40: Gal Shvinkelstein | C40: 24 | D40: 1115 | E40: 30 | F40: 24 | G40: שווי ארוחות | H40: 1000
A41: 32 | B41: Gal Sosin | C41: 3 | D41: 115 | E41: 32 | F41: 3 | G41: טלפון | H41: 230
A42: 32 | B42: Gal Sosin | C42: 24 | D42: 1115 | E42: 32 | F42: 24 | G42: שווי ארוחות | H42: 1000
A43: 35 | B43: Keren Zilberman | C43: 3 | D43: 115 | E43: 35 | F43: 3 | G43: טלפון | H43: 218.45
...

Sheet WHT_Findings
A1: {=_xlfn._xlws.PY(1,0,DeductionCodes,DeductionData,DedEmp,DedCode,DedName,DedValue)} -> No. | B1: Employee's name | C1: ItemName | D1: value | E1: Code | F1: Sign | G1: מספר עובד | H1: מספר ניכוי | I1: שם הניכוי | J1: סכום הניכוי | K1: SignedValue

Sheet SBC_Findings
A1: {=_xlfn._xlws.PY(2,0,SBCID,ClientID,SBCType,SBCdata,SBCcodes)} -> No. | B1: Employee's name | C1: System | D1: value | E1: מספר עובד | F1: מספר רכיב | G1: שם רכיב שכר | H1: סיכום ברוטו | L1: {=_xlfn._xlws.PY(3,0)} | M1: No. | N1: Employee's name | O1: Deductions | P1: value | Q1: מספר עובד | R1: מספר ניכוי | S1: שם הניכוי | T1: סכום הניכוי
L2: 2 | M2: 14 | N2: Danny Sabag | O2: 13 | P2: 131925.35 | Q2: 14 | R2: 13 | S2: מניות | T2: -131925.36
L3: 4 | M3: 21 | N3: Esther Shteinberg | O3: 13 | P3: 74739.424 | Q3: 21 | R3: 13 | S3: מניות | T3: -74739.43
L4: 10 | M4: 28 | N4: Tamir Leshetz | O4: 13 | P4: 41745.926 | Q4: 28 | R4: 13 | S4: מניות | T4: -41745.92
L5: 29 | M5: 68 | N5: Bar Zukerman | O5: 16 | P5: 21340.344 | Q5: 68 | R5: 16 | S5: אופציות | T5: -21340.35
L6: 38 | M6: 80 | N6: Ilya Rybak | O6: 13 | P6: 158059.51 | Q6: 80 | R6: 13 | S6: מניות | T6: -158059.5

Sheet Test
A1: {=_xlfn._xlws.PY(3,0)} | B1: No. | C1: Employee's name | D1: Deductions | E1: value | F1: מספר עובד | G1: מספר ניכוי | H1: שם הניכוי | I1: סכום הניכוי
A2: 2 | B2: 14 | C2: Danny Sabag | D2: 13 | E2: 131925.35 | F2: 14 | G2: 13 | H2: מניות | I2: -131925.36
A3: 4 | B3: 21 | C3: Esther Shteinberg | D3: 13 | E3: 74739.424 | F3: 21 | G3: 13 | H3: מניות | I3: -74739.43
A4: 10 | B4: 28 | C4: Tamir Leshetz | D4: 13 | E4: 41745.926 | F4: 28 | G4: 13 | H4: מניות | I4: -41745.92
A5: 29 | B5: 68 | C5: Bar Zukerman | D5: 16 | E5: 21340.344 | F5: 68 | G5: 16 | H5: אופציות | I5: -21340.35
A6: 38 | B6: 80 | C6: Ilya Rybak | D6: 13 | E6: 158059.51 | F6: 80 | G6: 13 | H6: מניות | I6: -158059.5
